Workbook
Name BudgetCategory: [1]!BudgetCategoryLookup[Budget Category Lookup]

Sheet All transactions
A1: Date | B1: Payee | C1: Amount | D1: Category | E1: Bas-Lux | F1: source
A2: 45861 | B2: Ext Credit Card Debit LITTLE UMBRELLA VANCOUVER BC | C2: 5.3 | D2: Dining | E2: Luxury | F2: ftcu
A3: 45860 | B3: Ext Credit Card Debit EXPEDIA HOTELCOM731800 UK.HOTELS.COMGB | C3: 156.07 | D3: Travel | E3: Luxury | F3: ftcu
A4: 45982 | B4: Ext Credit Card Debit BANK OF AMERICA SEATTLE DC | C4: -35 | D4: Cash | E4: Basic | F4: ftcu
A5: 45980 | B5: Ext Credit Card Credit PAYMENT - THANK YOU BEAVERTON OR | C5: -3.03 | D5: Transfer | E5: Basic | F5: ftcu
A6: 45929 | B6: Ext Credit Card Debit CASH ADVANCE BEAVERTON OR | C6: -104.55 | D6: Cash | E6: Basic | F6: ftcu
A7: 45923 | B7: Ext Credit Card Credit PAYMENT - THANK YOU BEAVERTON OR | C7: -303.86 | D7: Transfer | E7: Basic | F7: ftcu
A8: 45909 | B8: Ext Credit Card Credit PAYMENT - THANK YOU BEAVERTON OR | C8: -253 | D8: Transfer | E8: Basic | F8: ftcu
A9: 45909 | B9: Ext Credit Card Debit CASH ADVANCE BEAVERTON OR | C9: -316.57 | D9: Cash | E9: Basic | F9: ftcu
A10: 45898 | B10: Ext Credit Card Debit CASH ADVANCE BEAVERTON OR | C10: -203 | D10: Cash | E10: Basic | F10: ftcu
A11: 45889 | B11: Ext Credit Card Debit BANK OF AMERICA SEATTLE DC | C11: -8 | D11: Cash | E11: Basic | F11: ftcu
A12: 45878 | B12: Ext Credit Card Credit PAYMENT - THANK YOU BEAVERTON OR | C12: -32.31 | D12: Transfer | E12: Basic | F12: ftcu
A13: 45877 | B13: Ext Credit Card Credit PAYMENT - THANK YOU BEAVERTON OR | C13: -36.01 | D13: Transfer | E13: Basic | F13: ftcu
... A71: 45675 | B71: Ext Credit Card Debit Interest Charge on Cash A | C71: 148.68 | D71: Bank Fees | E71: Luxury | F71: ftcu
A72: 45835 | B72: Ext Credit Card Debit ZG * RENTAPPLICATION 206-516-2265 WA | C72: 35 | D72: 0 | E72: 0 | F72: ftcu
A73: 45828 | B73: Ext Credit Card Debit WAFISH&WILDLIC-SVC*FEE OLYMPIA WA | C73: 3.03 | D73: Travel | E73: Luxury | F73: ftcu
A74: 45828 | B74: Ext Credit Card Debit WA FISH & WILD LICENSE OLYMPIA WA | C74: 104.55 | D74: Travel | E74: Luxury | F74: ftcu
A75: 45801 | B75: Ext Credit Card Debit CL *TRIPCHARGES GLEN ALLEN VA | C75: 303.86 | D75: Travel | E75: Luxury | F75: ftcu
A76: 45789 | B76: Ext Credit Card Debit ACTBLUE* EILEEN.LAUBAC BOSTON MA | C76: 253 | D76: Charitable Contributions | E76: Luxury | F76: ftcu
A77: 45775 | B77: Ext Credit Card Debit CSAIRP90 WDP90725042679 PARIS FR | C77: 316.57 | D77: Travel | E77: Luxury | F77: ftcu
A78: 45709 | B78: Ext Credit Card Debit P462086 SEATTLE DC | C78: 203 | D78: 0 | E78: 0 | F78: ftcu
A79: 45868 | B79: Ext Credit Card Debit VM PARKING GARAGE SEATTLE WA | C79: 8 | D79: Auto | E79: Basic | F79: ftcu
A80: 45861 | B80: Ext Credit Card Debit HONK PARKING 866-675-7337 ON | C80: 32.31 | D80: Auto | E80: Basic | F80: ftcu
A81: 45857 | B81: Ext Credit Card Debit Interest Charge on Purcha | C81: 36.01 | D81: Bank Fees | E81: Luxury | F81: ftcu
A82: 45826 | B82: Ext Credit Card Debit Interest Charge on Purcha | C82: 32.91 | D82: Bank Fees | E82: Luxury | F82: ftcu
A83: 45796 | B83: Ext Credit Card Debit Interest Charge on Purcha | C83: 27.1 | D83: Bank Fees | E83: Luxury | F83: ftcu
A84: 45765 | B84: Ext Credit Card Debit Interest Charge on Purcha | C84: 27.1 | D84: Bank Fees | E84: Luxury | F84: ftcu
A85: 45735 | B85: Ext Credit Card Debit Interest Charge on Purcha | C85: 28.35 | D85: Bank Fees | E85: Luxury | F85: ftcu
A86: 45703 | B86: Ext Credit Card Debit Interest Charge on Purcha | C86: 37.87 | D86: Bank Fees | E86: Luxury | F86: ftcu
A87: 45675 | B87: Ext Credit Card Debit Interest Charge on Purcha | C87: 37.87 | D87: Bank Fees | E87: Luxury | F87: ftcu
A88: 45869 | B88: Ext Credit Card Debit EZELLS FAMOUS CHICKEN SEATTLE WA | C88: 34.97 | D88: Dining | E88: Luxury | F88: ftcu
A89: 45867 | B89: Ext Credit Card Debit CLEVER COW CREAMERY EASTSOUND WA | C89: 5.7 | D89: Dining | E89: Luxury | F89: ftcu
A90: 45866 | B90: Ext Credit Card Debit SQ *TAQUERIA AND PUPUS EASTSOUND WA | C90: 6.38 | D90: Dining | E90: Luxury | F90: ftcu
... A110: 45943 | B110: Ext Credit Card Credit 4297453 AUTOPAYLANG*!01 | C110: -11.53 | D110: Transfer | E110: Basic | F110: ftcu
A111: 45941 | B111: Lnvm | C111: 110.34 | E111: 0 | F111: usaa-cc
A112: 45981 | B112: Seattle University | C112: 19.5 | D112: Auto | E112: Basic | F112: usaa-cc
A113: 45954 | B113: Seattle University | C113: 10 | D113: Auto | E113: Basic | F113: usaa-cc
A114: 45946 | B114: Seattle University | C114: 30.91 | D114: Auto | E114: Basic | F114: usaa-cc
A115: 45944 | B115: Seattle University | C115: 15.59 | D115: Auto | E115: Basic | F115: usaa-cc
A116: 45963 | B116: Best Buy | C116: 308.97 | D116: Auto | E116: Basic | F116: usaa-cc
...

Sheet ftcu
A1: Date | B1: Payee | C1: Amount | D1: Category | E1: Bas-Lux | F1: source
A2: 45685 | B2: Ext Credit Card Credit PAYMENT - THANK YOU BEAVERTON OR | C2: -5000 | D2: =_xlfn.XLOOKUP(B2,'Payee Ref'!A:A,'Payee Ref'!B:B,"unassigned",0,1) -> Travel | E2: =_xlfn.XLOOKUP(B2,'Payee Ref'!A:A,'Payee Ref'!C:C,"unassigned",0,1) -> Luxury | F2: ftcu
A3: 45709 | B3: Ext Credit Card Credit PAYMENT - THANK YOU BEAVERTON OR | C3: -3000 | D3: =_xlfn.XLOOKUP(B3,'Payee Ref'!A:A,'Payee Ref'!B:B,"unassigned",0,1) -> Travel | E3: =_xlfn.XLOOKUP(B3,'Payee Ref'!A:A,'Payee Ref'!C:C,"unassigned",0,1) -> Luxury | F3: ftcu
A4: 45687 | B4: Ext Credit Card Credit PAYMENT - THANK YOU BEAVERTON OR | C4: -3000 | D4: =_xlfn.XLOOKUP(B4,'Payee Ref'!A:A,'Payee Ref'!B:B,"unassigned",0,1) -> Travel | E4: =_xlfn.XLOOKUP(B4,'Payee Ref'!A:A,'Payee Ref'!C:C,"unassigned",0,1) -> Luxury | F4: ftcu
A5: 45672 | B5: Ext Credit Card Credit PAYMENT - THANK YOU BEAVERTON OR | C5: -1200 | D5: =_xlfn.XLOOKUP(B5,'Payee Ref'!A:A,'Payee Ref'!B:B,"unassigned",0,1) -> Travel | E5: =_xlfn.XLOOKUP(B5,'Payee Ref'!A:A,'Payee Ref'!C:C,"unassigned",0,1) -> Luxury | F5: ftcu
A6: 45728 | B6: Ext Credit Card Credit PAYMENT - THANK YOU BEAVERTON OR | C6: -500 | D6: =_xlfn.XLOOKUP(B6,'Payee Ref'!A:A,'Payee Ref'!B:B,"unassigned",0,1) -> Travel | E6: =_xlfn.XLOOKUP(B6,'Payee Ref'!A:A,'Payee Ref'!C:C,"unassigned",0,1) -> Luxury | F6: ftcu
A7: 45909 | B7: Ext Credit Card Debit CASH ADVANCE BEAVERTON OR | C7: -316.57 | D7: =_xlfn.XLOOKUP(B7,'Payee Ref'!A:A,'Payee Ref'!B:B,"unassigned",0,1) -> Travel | E7: =_xlfn.XLOOKUP(B7,'Payee Ref'!A:A,'Payee Ref'!C:C,"unassigned",0,1) -> Luxury | F7: ftcu
A8: 45923 | B8: Ext Credit Card Credit PAYMENT - THANK YOU BEAVERTON OR | C8: -303.86 | D8: =_xlfn.XLOOKUP(B8,'Payee Ref'!A:A,'Payee Ref'!B:B,"unassigned",0,1) -> Travel | E8: =_xlfn.XLOOKUP(B8,'Payee Ref'!A:A,'Payee Ref'!C:C,"unassigned",0,1) -> Luxury | F8: ftcu
A9: 45909 | B9: Ext Credit Card Credit PAYMENT - THANK YOU BEAVERTON OR | C9: -253 | D9: =_xlfn.XLOOKUP(B9,'Payee Ref'!A:A,'Payee Ref'!B:B,"unassigned",0,1) -> Travel | E9: =_xlfn.XLOOKUP(B9,'Payee Ref'!A:A,'Payee Ref'!C:C,"unassigned",0,1) -> Luxury | F9: ftcu
A10: 45898 | B10: Ext Credit Card Debit CASH ADVANCE BEAVERTON OR | C10: -203 | D10: =_xlfn.XLOOKUP(B10,'Payee Ref'!A:A,'Payee Ref'!B:B,"unassigned",0,1) -> Travel | E10: =_xlfn.XLOOKUP(B10,'Payee Ref'!A:A,'Payee Ref'!C:C,"unassigned",0,1) -> Luxury | F10: ftcu
A11: 45929 | B11: Ext Credit Card Debit CASH ADVANCE BEAVERTON OR | C11: -104.55 | D11: =_xlfn.XLOOKUP(B11,'Payee Ref'!A:A,'Payee Ref'!B:B,"unassigned",0,1) -> Travel | E11: =_xlfn.XLOOKUP(B11,'Payee Ref'!A:A,'Payee Ref'!C:C,"unassigned",0,1) -> Luxury | F11: ftcu
A12: 45824 | B12: Ext Credit Card Debit CASH ADVANCE BEAVERTON OR | C12: -79.98 | D12: =_xlfn.XLOOKUP(B12,'Payee Ref'!A:A,'Payee Ref'!B:B,"unassigned",0,1) -> Travel | E12: =_xlfn.XLOOKUP(B12,'Payee Ref'!A:A,'Payee Ref'!C:C,"unassigned",0,1) -> Luxury | F12: ftcu
A13: 45829 | B13: Ext Credit Card Debit CASH ADVANCE BEAVERTON OR | C13: -73.19 | D13: =_xlfn.XLOOKUP(B13,'Payee Ref'!A:A,'Payee Ref'!B:B,"unassigned",0,1) -> Travel | E13: =_xlfn.XLOOKUP(B13,'Payee Ref'!A:A,'Payee Ref'!C:C,"unassigned",0,1) -> Luxury | F13: ftcu
... A110: 45715 | B110: Ext Credit Card Debit CASH ADVANCE BEAVERTON OR | C110: 22456.46 | D110: =_xlfn.XLOOKUP(B110,'Payee Ref'!A:A,'Payee Ref'!B:B,"unassigned",0,1) -> Travel | E110: =_xlfn.XLOOKUP(B110,'Payee Ref'!A:A,'Payee Ref'!C:C,"unassigned",0,1) -> Luxury | F110: ftcu
C111: =SUM(C2:C110) -> 13634.89 | E111: =SUM(E2:E110) -> 0

Sheet amex
A1: Date | B1: Payee | C1: Amount | D1: Category | E1: Bas-Lux | F1: source
A2: 45984 | B2: CURSOR, AI POWERED INEW YORK NY | C2: 22.07 | D2: =_xlfn.XLOOKUP(B2,'Payee Ref'!A:A,'Payee Ref'!B:B,"unassigned",0,1) -> Travel | E2: =_xlfn.XLOOKUP(B2,'Payee Ref'!A:A,'Payee Ref'!C:C,"unassigned",0,1) -> Luxury | F2: amex
A3: 45984 | B3: TST* TASTE OF INDIA SEATTLE WA | C3: 96.53 | D3: =_xlfn.XLOOKUP(B3,'Payee Ref'!A:A,'Payee Ref'!B:B,"unassigned",0,1) -> Dining | E3: =_xlfn.XLOOKUP(B3,'Payee Ref'!A:A,'Payee Ref'!C:C,"unassigned",0,1) -> Luxury | F3: amex
A4: 45983 | B4: ONLINE PAYMENT - THANK YOU | C4: -5520.71 | D4: =_xlfn.XLOOKUP(B4,'Payee Ref'!A:A,'Payee Ref'!B:B,"unassigned",0,1) -> Transfer | E4: =_xlfn.XLOOKUP(B4,'Payee Ref'!A:A,'Payee Ref'!C:C,"unassigned",0,1) -> Basic | F4: amex
A5: 45980 | B5: 46630 N BEND WAY 574NORTH BEND WA | C5: 61.81 | D5: =_xlfn.XLOOKUP(B5,'Payee Ref'!A:A,'Payee Ref'!B:B,"unassigned",0,1) -> Auto | E5: =_xlfn.XLOOKUP(B5,'Payee Ref'!A:A,'Payee Ref'!C:C,"unassigned",0,1) -> Basic | F5: amex
A6: 45980 | B6: DUNN LUMBER CO BELLEVUE WA | C6: 983.46 | D6: =_xlfn.XLOOKUP(B6,'Payee Ref'!A:A,'Payee Ref'!B:B,"unassigned",0,1) -> Travel | E6: =_xlfn.XLOOKUP(B6,'Payee Ref'!A:A,'Payee Ref'!C:C,"unassigned",0,1) -> Luxury | F6: amex
A7: 45980 | B7: PIE FOR THE PEOPLE NSNOQUALMIE PASS WA | C7: 9 | D7: =_xlfn.XLOOKUP(B7,'Payee Ref'!A:A,'Payee Ref'!B:B,"unassigned",0,1) -> Dining | E7: =_xlfn.XLOOKUP(B7,'Payee Ref'!A:A,'Payee Ref'!C:C,"unassigned",0,1) -> Luxury | F7: amex
A8: 45979 | B8: CLAUDE.AI SUBSCRIPTISAN FRANCISCO CA | C8: 97.74 | D8: =_xlfn.XLOOKUP(B8,'Payee Ref'!A:A,'Payee Ref'!B:B,"unassigned",0,1) -> Travel | E8: =_xlfn.XLOOKUP(B8,'Payee Ref'!A:A,'Payee Ref'!C:C,"unassigned",0,1) -> Luxury | F8: amex
A9: 45979 | B9: LEE'S SUMMIT DELI & SNOQUALMIE PS WA | C9: 2.79 | D9: =_xlfn.XLOOKUP(B9,'Payee Ref'!A:A,'Payee Ref'!B:B,"unassigned",0,1) -> Dining | E9: =_xlfn.XLOOKUP(B9,'Payee Ref'!A:A,'Payee Ref'!C:C,"unassigned",0,1) -> Luxury | F9: amex
A10: 45979 | B10: PIE FOR THE PEOPLE NSNOQUALMIE PASS WA | C10: 9 | D10: =_xlfn.XLOOKUP(B10,'Payee Ref'!A:A,'Payee Ref'!B:B,"unassigned",0,1) -> Dining | E10: =_xlfn.XLOOKUP(B10,'Payee Ref'!A:A,'Payee Ref'!C:C,"unassigned",0,1) -> Luxury | F10: amex
A11: 45978 | B11: 46630 N BEND WAY 574NORTH BEND WA | C11: 68.92 | D11: =_xlfn.XLOOKUP(B11,'Payee Ref'!A:A,'Payee Ref'!B:B,"unassigned",0,1) -> Auto | E11: =_xlfn.XLOOKUP(B11,'Payee Ref'!A:A,'Payee Ref'!C:C,"unassigned",0,1) -> Basic | F11: amex
A12: 45978 | B12: EZELLS FAMOUS CHICKESEATTLE WA | C12: 28.29 | D12: =_xlfn.XLOOKUP(B12,'Payee Ref'!A:A,'Payee Ref'!B:B,"unassigned",0,1) -> Dining | E12: =_xlfn.XLOOKUP(B12,'Payee Ref'!A:A,'Payee Ref'!C:C,"unassigned",0,1) -> Luxury | F12: amex
A13: 45978 | B13: PAYPAL *WORLDFOOTBA 9708709898 CO | C13: 34.5 | D13: =_xlfn.XLOOKUP(B13,'Payee Ref'!A:A,'Payee Ref'!B:B,"unassigned",0,1) -> Enrichment | E13: =_xlfn.XLOOKUP(B13,'Payee Ref'!A:A,'Payee Ref'!C:C,"unassigned",0,1) -> Luxury | F13: amex
... A756: 45658 | B756: SUMMIT AT SNOQUALMIESNOQUALMIE PASS WA | C756: 121.3 | D756: =_xlfn.XLOOKUP(B756,'Payee Ref'!A:A,'Payee Ref'!B:B,"unassigned",0,1) -> Enrichment | E756: =_xlfn.XLOOKUP(B756,'Payee Ref'!A:A,'Payee Ref'!C:C,"unassigned",0,1) -> Basic | F756: amex

Sheet usaa-cc
A1: Date | B1: Payee | C1: Amount | D1: Category | E1: Bas-lux | F1: source
A2: 45860 | B2: USAA CREDIT CARD PAYMENT SAN ANTONIO TX | C2: -23350.85 | D2: =_xlfn.XLOOKUP(B2,'Payee Ref'!A:A,'Payee Ref'!B:B,"unassigned",0,1) -> Credit Card Payment | E2: =_xlfn.XLOOKUP(B2,'Payee Ref'!A:A,'Payee Ref'!C:C,"unassigned",0,1) -> Basic | F2: usaa-cc
A3: 45905 | B3: USAA CREDIT CARD PAYMENT SAN ANTONIO TX | C3: -21348.38 | D3: =_xlfn.XLOOKUP(B3,'Payee Ref'!A:A,'Payee Ref'!B:B,"unassigned",0,1) -> Credit Card Payment | E3: =_xlfn.XLOOKUP(B3,'Payee Ref'!A:A,'Payee Ref'!C:C,"unassigned",0,1) -> Basic | F3: usaa-cc
A4: 45802 | B4: USAA CREDIT CARD PAYMENT SAN ANTONIO TX | C4: -20000 | D4: =_xlfn.XLOOKUP(B4,'Payee Ref'!A:A,'Payee Ref'!B:B,"unassigned",0,1) -> Credit Card Payment | E4: =_xlfn.XLOOKUP(B4,'Payee Ref'!A:A,'Payee Ref'!C:C,"unassigned",0,1) -> Basic | F4: usaa-cc
A5: 45963 | B5: USAA Credit Card | C5: -15691.03 | D5: =_xlfn.XLOOKUP(B5,'Payee Ref'!A:A,'Payee Ref'!B:B,"unassigned",0,1) -> Transfer | E5: =_xlfn.XLOOKUP(B5,'Payee Ref'!A:A,'Payee Ref'!C:C,"unassigned",0,1) -> Basic | F5: usaa-cc
A6: 45748 | B6: USAA CREDIT CARD PAYMENT SAN ANTONIO TX | C6: -15000 | D6: =_xlfn.XLOOKUP(B6,'Payee Ref'!A:A,'Payee Ref'!B:B,"unassigned",0,1) -> Credit Card Payment | E6: =_xlfn.XLOOKUP(B6,'Payee Ref'!A:A,'Payee Ref'!C:C,"unassigned",0,1) -> Basic | F6: usaa-cc
A7: 45993 | B7: USAA JJK MDS VISA PAYMENT ***********5521 | C7: -14014.11 | D7: =_xlfn.XLOOKUP(B7,'Payee Ref'!A:A,'Payee Ref'!B:B,"unassigned",0,1) -> unassigned | E7: =_xlfn.XLOOKUP(B7,'Payee Ref'!A:A,'Payee Ref'!C:C,"unassigned",0,1) -> unassigned | F7: usaa-cc
A8: 45822 | B8: USAA CREDIT CARD PAYMENT SAN ANTONIO TX | C8: -13188.92 | D8: =_xlfn.XLOOKUP(B8,'Payee Ref'!A:A,'Payee Ref'!B:B,"unassigned",0,1) -> Credit Card Payment | E8: =_xlfn.XLOOKUP(B8,'Payee Ref'!A:A,'Payee Ref'!C:C,"unassigned",0,1) -> Basic | F8: usaa-cc
A9: 45873 | B9: USAA CREDIT CARD PAYMENT SAN ANTONIO TX | C9: -10000 | D9: =_xlfn.XLOOKUP(B9,'Payee Ref'!A:A,'Payee Ref'!B:B,"unassigned",0,1) -> Credit Card Payment | E9: =_xlfn.XLOOKUP(B9,'Payee Ref'!A:A,'Payee Ref'!C:C,"unassigned",0,1) -> Basic | F9: usaa-cc
A10: 45737 | B10: USAA CREDIT CARD PAYMENT SAN ANTONIO TX | C10: -10000 | D10: =_xlfn.XLOOKUP(B10,'Payee Ref'!A:A,'Payee Ref'!B:B,"unassigned",0,1) -> Credit Card Payment | E10: =_xlfn.XLOOKUP(B10,'Payee Ref'!A:A,'Payee Ref'!C:C,"unassigned",0,1) -> Basic | F10: usaa-cc
A11: 45724 | B11: USAA CREDIT CARD PAYMENT SAN ANTONIO TX | C11: -10000 | D11: =_xlfn.XLOOKUP(B11,'Payee Ref'!A:A,'Payee Ref'!B:B,"unassigned",0,1) -> Credit Card Payment | E11: =_xlfn.XLOOKUP(B11,'Payee Ref'!A:A,'Payee Ref'!C:C,"unassigned",0,1) -> Basic | F11: usaa-cc
A12: 45696 | B12: USAA CREDIT CARD PAYMENT SAN ANTONIO TX | C12: -10000 | D12: =_xlfn.XLOOKUP(B12,'Payee Ref'!A:A,'Payee Ref'!B:B,"unassigned",0,1) -> Credit Card Payment | E12: =_xlfn.XLOOKUP(B12,'Payee Ref'!A:A,'Payee Ref'!C:C,"unassigned",0,1) -> Basic | F12: usaa-cc
A13: 45659 | B13: USAA CREDIT CARD PAYMENT SAN ANTONIO TX | C13: -10000 | D13: =_xlfn.XLOOKUP(B13,'Payee Ref'!A:A,'Payee Ref'!B:B,"unassigned",0,1) -> Credit Card Payment | E13: =_xlfn.XLOOKUP(B13,'Payee Ref'!A:A,'Payee Ref'!C:C,"unassigned",0,1) -> Basic | F13: usaa-cc
... A1930: 45977 | B1930: USAA Insurance Payment | C1930: 1233.47 | D1930: =_xlfn.XLOOKUP(B1930,'Payee Ref'!A:A,'Payee Ref'!B:B,"unassigned",0,1) -> Insurance | E1930: =_xlfn.XLOOKUP(B1930,'Payee Ref'!A:A,'Payee Ref'!C:C,"unassigned",0,1) -> Basic | F1930: usaa-cc
A1931: 46006 | B1931: USAA INSURANCE BILL PAYMENT | C1931: 1233.93 | E1931: =_xlfn.XLOOKUP(B1931,'Payee Ref'!A:A,'Payee Ref'!C:C,"unassigned",0,1) -> Basic | F1931: usaa-cc
A1932: 45823 | B1932: USAA INSURANCE PAYMENT WWW.USAA.COM TX | C1932: 1255.59 | D1932: =_xlfn.XLOOKUP(B1932,'Payee Ref'!A:A,'Payee Ref'!B:B,"unassigned",0,1) -> Insurance | E1932: =_xlfn.XLOOKUP(B1932,'Payee Ref'!A:A,'Payee Ref'!C:C,"unassigned",0,1) -> Basic | F1932: usaa-cc
A1933: 45792 | B1933: USAA INSURANCE PAYMENT WWW.USAA.COM TX | C1933: 1255.65 | D1933: =_xlfn.XLOOKUP(B1933,'Payee Ref'!A:A,'Payee Ref'!B:B,"unassigned",0,1) -> Insurance | E1933: =_xlfn.XLOOKUP(B1933,'Payee Ref'!A:A,'Payee Ref'!C:C,"unassigned",0,1) -> Basic | F1933: usaa-cc
A1934: 45762 | B1934: USAA INSURANCE PAYMENT WWW.USAA.COM TX | C1934: 1255.65 | D1934: =_xlfn.XLOOKUP(B1934,'Payee Ref'!A:A,'Payee Ref'!B:B,"unassigned",0,1) -> Insurance | E1934: =_xlfn.XLOOKUP(B1934,'Payee Ref'!A:A,'Payee Ref'!C:C,"unassigned",0,1) -> Basic | F1934: usaa-cc
A1935: 45731 | B1935: USAA INSURANCE PAYMENT WWW.USAA.COM TX | C1935: 1255.65 | D1935: =_xlfn.XLOOKUP(B1935,'Payee Ref'!A:A,'Payee Ref'!B:B,"unassigned",0,1) -> Insurance | E1935: =_xlfn.XLOOKUP(B1935,'Payee Ref'!A:A,'Payee Ref'!C:C,"unassigned",0,1) -> Basic | F1935: usaa-cc
A1936: 45703 | B1936: USAA INSURANCE PAYMENT WWW.USAA.COM TX | C1936: 1255.65 | D1936: =_xlfn.XLOOKUP(B1936,'Payee Ref'!A:A,'Payee Ref'!B:B,"unassigned",0,1) -> Insurance | E1936: =_xlfn.XLOOKUP(B1936,'Payee Ref'!A:A,'Payee Ref'!C:C,"unassigned",0,1) -> Basic | F1936: usaa-cc
A1937: 45853 | B1937: USAA INSURANCE PAYMENT WWW.USAA.COM TX | C1937: 1288.96 | D1937: =_xlfn.XLOOKUP(B1937,'Payee Ref'!A:A,'Payee Ref'!B:B,"unassigned",0,1) -> Insurance | E1937: =_xlfn.XLOOKUP(B1937,'Payee Ref'!A:A,'Payee Ref'!C:C,"unassigned",0,1) -> Basic | F1937: usaa-cc
A1938: 45697 | B1938: SQ *KATE GROSSMAN MD PLLCgosq.com WA | C1938: 1360 | D1938: =_xlfn.XLOOKUP(B1938,'Payee Ref'!A:A,'Payee Ref'!B:B,"unassigned",0,1) -> Health & Medical | E1938: =_xlfn.XLOOKUP(B1938,'Payee Ref'!A:A,'Payee Ref'!C:C,"unassigned",0,1) -> Basic | F1938: usaa-cc
A1939: 45672 | B1939: USAA INSURANCE PAYMENT WWW.USAA.COM TX | C1939: 1418.43 | D1939: =_xlfn.XLOOKUP(B1939,'Payee Ref'!A:A,'Payee Ref'!B:B,"unassigned",0,1) -> Insurance | E1939: =_xlfn.XLOOKUP(B1939,'Payee Ref'!A:A,'Payee Ref'!C:C,"unassigned",0,1) -> Basic | F1939: usaa-cc
A1940: 45739 | B1940: OPTUM CARE WA MY CHART 425-258-3900 WA | C1940: 1427.5 | D1940: =_xlfn.XLOOKUP(B1940,'Payee Ref'!A:A,'Payee Ref'!B:B,"unassigned",0,1) -> Health & Medical | E1940: =_xlfn.XLOOKUP(B1940,'Payee Ref'!A:A,'Payee Ref'!C:C,"unassigned",0,1) -> Basic | F1940: usaa-cc
A1941: 45723 | B1941: GB* SEATTLE JAZZED GIVEBUTTER.CODE | C1941: 1547.11 | D1941: =_xlfn.XLOOKUP(B1941,'Payee Ref'!A:A,'Payee Ref'!B:B,"unassigned",0,1) -> Charitable Contributions | E1941: =_xlfn.XLOOKUP(B1941,'Payee Ref'!A:A,'Payee Ref'!C:C,"unassigned",0,1) -> Basic | F1941: usaa-cc
A1942: 45795 | B1942: GLAZER'S CAMERA SEATTLE WA | C1942: 1595.61 | D1942: =_xlfn.XLOOKUP(B1942,'Payee Ref'!A:A,'Payee Ref'!B:B,"unassigned",0,1) -> Extracirricular | E1942: =_xlfn.XLOOKUP(B1942,'Payee Ref'!A:A,'Payee Ref'!C:C,"unassigned",0,1) -> Basic | F1942: usaa-cc
A1943: 45822 | B1943: SQ *KATE GROSSMAN MD PLLCgosq.com WA | C1943: 1700 | D1943: =_xlfn.XLOOKUP(B1943,'Payee Ref'!A:A,'Payee Ref'!B:B,"unassigned",0,1) -> Health & Medical | E1943: =_xlfn.XLOOKUP(B1943,'Payee Ref'!A:A,'Payee Ref'!C:C,"unassigned",0,1) -> Basic | F1943: usaa-cc
... A1954: 45862 | B1954: IN *WRIGHT DESIGNS LLC 360-5727839 WA | C1954: 9010.41 | D1954: =_xlfn.XLOOKUP(B1954,'Payee Ref'!A:A,'Payee Ref'!B:B,"unassigned",0,1) -> Van | E1954: =_xlfn.XLOOKUP(B1954,'Payee Ref'!A:A,'Payee Ref'!C:C,"unassigned",0,1) -> Luxury | F1954: usaa-cc

Sheet boa-cc
A1: Date | B1: Payee | C1: Amount | D1: Category | E1: Bas-lux | F1: source
A2: 45652 | B2: REMARKABLE OSLO | C2: -3.3 | D2: =_xlfn.XLOOKUP(B2,'Payee Ref'!A:A,'Payee Ref'!B:B,"unassigned",0,1) -> Subscriptions / Digital | E2: =_xlfn.XLOOKUP(B2,'Payee Ref'!A:A,'Payee Ref'!C:C,"unassigned",0,1) -> Luxury | F2: boa-cc
A3: 45652 | B3: SEA AIRPORT PARKING 2067874069 WA | C3: -32 | D3: =_xlfn.XLOOKUP(B3,'Payee Ref'!A:A,'Payee Ref'!B:B,"unassigned",0,1) -> Parking | E3: =_xlfn.XLOOKUP(B3,'Payee Ref'!A:A,'Payee Ref'!C:C,"unassigned",0,1) -> Basic | F3: boa-cc
A4: 45652 | B4: QFC #5807 SEATTLE WA | C4: -14.46 | D4: =_xlfn.XLOOKUP(B4,'Payee Ref'!A:A,'Payee Ref'!B:B,"unassigned",0,1) -> Groceries | E4: =_xlfn.XLOOKUP(B4,'Payee Ref'!A:A,'Payee Ref'!C:C,"unassigned",0,1) -> Basic | F4: boa-cc
A5: 45652 | B5: QFC #5807 SEATTLE WA | C5: -5.79 | D5: =_xlfn.XLOOKUP(B5,'Payee Ref'!A:A,'Payee Ref'!B:B,"unassigned",0,1) -> Groceries | E5: =_xlfn.XLOOKUP(B5,'Payee Ref'!A:A,'Payee Ref'!C:C,"unassigned",0,1) -> Basic | F5: boa-cc
A6: 45652 | B6: CRYSTAL MOUNTAIN 360-663-3020 WA | C6: -146.75 | D6: =_xlfn.XLOOKUP(B6,'Payee Ref'!A:A,'Payee Ref'!B:B,"unassigned",0,1) -> Travel | E6: =_xlfn.XLOOKUP(B6,'Payee Ref'!A:A,'Payee Ref'!C:C,"unassigned",0,1) -> Luxury | F6: boa-cc
A7: 45652 | B7: SEA SMITH COVE 6951113 888-3100583 WA | C7: -51.85 | D7: =_xlfn.XLOOKUP(B7,'Payee Ref'!A:A,'Payee Ref'!B:B,"unassigned",0,1) -> Dining | E7: =_xlfn.XLOOKUP(B7,'Payee Ref'!A:A,'Payee Ref'!C:C,"unassigned",0,1) -> Luxury | F7: boa-cc
A8: 45653 | B8: BA ELECTRONIC PAYMENT | C8: 7140.54 | D8: =_xlfn.XLOOKUP(B8,'Payee Ref'!A:A,'Payee Ref'!B:B,"unassigned",0,1) -> Credit Card Payment | E8: =_xlfn.XLOOKUP(B8,'Payee Ref'!A:A,'Payee Ref'!C:C,"unassigned",0,1) -> Basic | F8: boa-cc
A9: 45653 | B9: IN *SHADES BY MARKHAM LLC425-4430156 WA | C9: -2328.97 | D9: =_xlfn.XLOOKUP(B9,'Payee Ref'!A:A,'Payee Ref'!B:B,"unassigned",0,1) -> Home & Garden | E9: =_xlfn.XLOOKUP(B9,'Payee Ref'!A:A,'Payee Ref'!C:C,"unassigned",0,1) -> Basic | F9: boa-cc
A10: 45653 | B10: HUNGRYROOT.COM HUNGRYROOT.CONY | C10: -127.67 | D10: =_xlfn.XLOOKUP(B10,'Payee Ref'!A:A,'Payee Ref'!B:B,"unassigned",0,1) -> Groceries | E10: =_xlfn.XLOOKUP(B10,'Payee Ref'!A:A,'Payee Ref'!C:C,"unassigned",0,1) -> Basic | F10: boa-cc
A11: 45654 | B11: MAPLE LEAF ACE SEATTLE WA | C11: -78.75 | D11: =_xlfn.XLOOKUP(B11,'Payee Ref'!A:A,'Payee Ref'!B:B,"unassigned",0,1) -> Home & Garden | E11: =_xlfn.XLOOKUP(B11,'Payee Ref'!A:A,'Payee Ref'!C:C,"unassigned",0,1) -> Basic | F11: boa-cc
A12: 45656 | B12: NYTIMES* 800-698-4637 NY | C12: -25.55 | D12: =_xlfn.XLOOKUP(B12,'Payee Ref'!A:A,'Payee Ref'!B:B,"unassigned",0,1) -> Subscriptions / Digital | E12: =_xlfn.XLOOKUP(B12,'Payee Ref'!A:A,'Payee Ref'!C:C,"unassigned",0,1) -> Luxury | F12: boa-cc
A13: 45656 | B13: FULLSCRIPT* R588685504 HTTPSUS.FULLSNH | C13: -120.97 | D13: =_xlfn.XLOOKUP(B13,'Payee Ref'!A:A,'Payee Ref'!B:B,"unassigned",0,1) -> Personal Care | E13: =_xlfn.XLOOKUP(B13,'Payee Ref'!A:A,'Payee Ref'!C:C,"unassigned",0,1) -> Basic | F13: boa-cc
... A375: 45986 | B375: BA ELECTRONIC PAYMENT | C375: 7402.41 | D375: =_xlfn.XLOOKUP(B375,'Payee Ref'!A:A,'Payee Ref'!B:B,"unassigned",0,1) -> Credit Card Payment | E375: =_xlfn.XLOOKUP(B375,'Payee Ref'!A:A,'Payee Ref'!C:C,"unassigned",0,1) -> Basic | F375: boa-cc

Sheet Payee Ref
A2: Payee | B2: proper | C2: Basic/Luxury | D2: Note
A3: *LAKE CITY SEATTLE W
A4: 4490 SOUTH STATE 100MOUNT CARMEL UT | B4: Dining | C4: Luxury
A5: 46630 N BEND WAY 574NORTH BEND WA | B5: Auto | C5: Basic
A6: 46630 N BEND WAY 574NORTH BEND WA | B6: Auto | C6: Basic
A7: 6951310 - PEET'S COFSEATTLE WA | B7: Dining | C7: Luxury
A8: 7-ELEVEN 23020 SEATTLE WA | B8: Groceries | C8: Luxury | D8: should be groceries
A9: 7-ELEVEN T3 #03-12 SINGAPORE SG | B9: Travel | C9: Luxury
A10: 76 - CF UNITED APRO LLC 2BELLEVUE WA | B10: Auto | C10: Basic | D10: create category "fuel"
A11: 76 - CHELAN 76 CHELAN WA | B11: Auto | C11: Basic
A12: 76 - HUNGRY BEAR MARKET BELLEVUE WA | B12: Groceries | C12: Basic
A13: 76 - MARKET PLACE ORONDO WA | B13: Groceries | C13: Basic
A14: 76 - ROOSEVELT 76 SEATTLE WA | B14: Auto | C14: Basic
A15: 76 - THE POINT SEATTLE WA | B15: Auto | C15: Basic
A16: 76 - VILLAGE MARKET 76 SEATTLE WA | B16: Auto | C16: Basic | D16: create category "fuel"
A17: 76 Fuel | B17: Auto | C17: Basic
A18: 7E - TERMINAL 2 SINGAPORE SG | B18: Travel | C18: Luxury
A19: 8020 Inc | B19: Van | C19: Luxury
A20: A Bottle | B20: Dining | C20: Luxury
A21: A Saily | B21: Travel | C21: Luxury
A22: a.saily Lewes DE | B22: Dining | C22: Luxury
A23: AAA Membership | B23: Membership | C23: Basic
A24: AAA WA MEMBERSHIP 00 800-562-2582 WA | B24: Membership | C24: Basic
A25: AAA WA MEMBERSHIP 01 800-562-2582 WA | B25: Auto | C25: Basic
A26: ACT THEATRE WEB 206-292-7660 WA | B26: R&R | C26: Luxury | D26: shorten to R&R
A27: 81394 - WESTLAKE & TERRY SEATTLE WA
A28: ADOBE Adobe Systems SAN JOSE CA | B28: Subscriptions / Digital | C28: Luxury
A29: AER LINGUS DUBLIN CO | B29: Travel | C29: Luxury
A30: AEROP. ADOLFO SUAREZ MADRMADRID ES | B30: Travel | C30: Luxury
A31: Airbnb | B31: Travel | C31: Luxury
A32: ALADDIN GYRO RESTAURSEATTLE WA | B32: Dining | C32: Luxury
A33: Alain Bellem | B33: Home & Garden | C33: Luxury | D33: Tip for movers
A34: ALASKA AIR 0272394527601SEATTLE WA | B34: Travel | C34: Luxury | D34: shorten to travel
A35: ALASKA AIRLINES SEATTLE WA | B35: Travel | C35: Luxury
A36: ALCAMPO LOGRONO LOGRONO ES | B36: Travel | C36: Luxury
A37: ALIMENTACION PRIMOS LOGRONO ES | B37: Travel | C37: Luxury
A38: ALL THE BEST PET CARE 206-529-8000 WA | B38: Pets | C38: Luxury | D38: no change
A39: ALOFT TOKYO GINZA -C* JP | B39: Travel | C39: Luxury
A40: Amazon | B40: Home & Garden | C40: Basic
A41: AMAZON MARKEPLACE NA PA | B41: Home & Garden | C41: Basic
...

Sheet Sheet7
A1: Van | B1: Luxury
A2: Van | B2: Basic
A3: Utilities | B3: Basic
A4: Unknown | B4: Basic
A5: Travel | B5: Luxury
A6: Travel | B6: Basic
A7: Transportation | B7: Basic
A8: Transfer
A9: Transfer | B9: Basic
A10: Syc | B10: Luxury
A11: Subscriptions / Digital | B11: Luxury | L11: V. FREITAS LAW, PLLC v@vfreitaslawWA
A12: Subscriptions / Digital | B12: Basic | L12: SP FELLOW PRODUCTS FELLOWPRODUCTCA
A13: R&R | B13: Luxury | L13: POKE ALICE 2 SEATTLE WA
A14: Professional | B14: Luxury | L14: TST*BA BAR - SOUTH LAKE Seattle WA
A15: Professional | B15: Basic | L15: SHORELINE SCHOOL DISTRICT206-3934215 WA
A16: Pharmacy | B16: Basic | L16: ALASKA AIR SEATTLE WA
A17: Pets | B17: Luxury | L17: ALASKA AIR 0272105262086SEATTLE WA
A18: Personal Care | B18: Basic | L18: ALASKA AIR 0272105259538SEATTLE WA
A19: Parking | B19: Basic | L19: ALASKA AIR 0272105260140SEATTLE WA
A20: Mortgage | B20: Basic | L20: ALASKA AIR 0272105260139SEATTLE WA
A21: Membership | B21: Basic | L21: NORDRACKCOM8889666283 888-966-6283 CA
A22: Membership | B22: Luxury | L22: TM *JON BATISTE 800-653-8000 CA
... A36: Gardener | B36: Luxury | L36: TST*RUBINSTEIN BAGELS - Seattle WA
A37: fue | L37: PAYPAL *IEFSPACESPT 91051816
A38: Extracirricular | B38: Basic | L38: TST*EL CAMION - SAND POI Seattle WA
A39: Enrichment | B39: Luxury | L39: SQ *JOEY UNIVERSITY VILLASeattle WA
A40: Enrichment | B40: Basic | L40: ALLIANZ TRAVEL INS ALLIANZINS.USVA
A41: Education: Secondary | B41: Basic | L41: as.Saily*saily Lewes DE
A42: Dining | B42: Luxury | L42: ALASKA AIR 0272109051092SEATTLE WA
A43: Dining | B43: Basic | L43: AIRBNB * HMKNBQB23F AIRBNB.COM CA
A44: Credit Card Payment | B44: Basic | L44: CACHITO MIO LARDERO
A45: Clothing | B45: Luxury | L45: MIKONOS GRAN VIA LOGRONO
A46: Clothing | B46: Basic | L46: SIMPLY CHILE LOGRONO
A47: Charitable Contributions | B47: Basic | L47: AIRBNB * HMSBE25BKD AIRBNB.COM CA
A48: Cash | B48: Basic | L48: WA DEPT OF HEALTH HSQA 360-236-4508 WA
A49: Boat | B49: Basic | L49: DECATHLON LOGRONO LOGRONO
... A53: Auto | B53: Luxury | L53: TST*BELLE EPICUREAN - EA Seattle WA
L54: SP SPIRITUAL GANGSTE SPIRITUALGANGCA
L55: TST*THE BRYANT CORNER CA Seattle WA
L56: PAYPAL *WORLDPACKER 786-897-1926 FL
...
